Workbook

Sheet Read_Me
A1: THE VALUATION GAP: Coca-Cola (KO) vs PepsiCo (PEP): calculation workbook
A3: Inputs sheet: values keyed from SEC 10-K filings (blue = hard-coded reported inputs; USD millions except EPS and price). Each row cites the 10-K accession and URL.
A4: Calculations / Summary sheets: all black cells are live formulas that reference Inputs.
A5: Verification sheet: the 50 income-statement figures that were matched to the visible text of the 10-K documents.
A6: Checks sheet: workbook results compared with the CSV used in Tableau (all differences must be ~0).
A7: Valuation date: close on 2025-12-31 (calendar year-end) for both companies; P/E = close / FY diluted GAAP EPS. PEP fiscal year ends Dec 27, 2025 (disclosed offset).
A8: Prices: Yahoo Finance chart API, unadjusted close (secondary source; not independently re-verified).
A9: Student portfolio project using public data. Not investment advice. Not affiliated with The Coca-Cola Company or PepsiCo, Inc.

Sheet Inputs
A1: Company | B1: Ticker | C1: Fiscal_Year | D1: Fiscal_Year_End | E1: Revenue_USD_M | F1: Prior_Year_Revenue_USD_M | G1: Gross_Profit_USD_M | H1: Operating_Income_USD_M | I1: Net_Income_USD_M | J1: Prior_Year_Net_Income_USD_M | K1: Total_Assets_USD_M | L1: EPS_Diluted_USD | M1: Close_Price_USD | N1: Price_Date | O1: 10-K_Accession | P1: 10-K_URL | Q1: Figures_Text_Verified_of_5
A2: The Coca-Cola Company | B2: KO | C2: 2021 | D2: 2021-12-31 | E2: 38655 | F2: 33014 | G2: 23298 | H2: 10308 | I2: 9771 | J2: 7747 | K2: 94354 | L2: 2.25 | M2: 59.209999 | N2: 2021-12-31 | O2: 0000021344-22-000009 | P2: https://www.sec.gov/Archives/edgar/data/21344/000002134422000009/ko-20211231.htm | Q2: 5
A3: The Coca-Cola Company | B3: KO | C3: 2022 | D3: 2022-12-31 | E3: 43004 | F3: 38655 | G3: 25004 | H3: 10909 | I3: 9542 | J3: 9771 | K3: 92763 | L3: 2.19 | M3: 63.610001 | N3: 2022-12-30 | O3: 0000021344-23-000011 | P3: https://www.sec.gov/Archives/edgar/data/21344/000002134423000011/ko-20221231.htm | Q3: 5
A4: The Coca-Cola Company | B4: KO | C4: 2023 | D4: 2023-12-31 | E4: 45754 | F4: 43004 | G4: 27234 | H4: 11311 | I4: 10714 | J4: 9542 | K4: 97703 | L4: 2.47 | M4: 58.93 | N4: 2023-12-29 | O4: 0000021344-24-000009 | P4: https://www.sec.gov/Archives/edgar/data/21344/000002134424000009/ko-20231231.htm | Q4: 5
A5: The Coca-Cola Company | B5: KO | C5: 2024 | D5: 2024-12-31 | E5: 47061 | F5: 45754 | G5: 28737 | H5: 9992 | I5: 10631 | J5: 10714 | K5: 100549 | L5: 2.46 | M5: 62.259998 | N5: 2024-12-31 | O5: 0000021344-25-000011 | P5: https://www.sec.gov/Archives/edgar/data/21344/000002134425000011/ko-20241231.htm | Q5: 5
A6: The Coca-Cola Company | B6: KO | C6: 2025 | D6: 2025-12-31 | E6: 47941 | F6: 47061 | G6: 29544 | H6: 13762 | I6: 13107 | J6: 10631 | K6: 104816 | L6: 3.04 | M6: 69.910004 | N6: 2025-12-31 | O6: 0001628280-26-010047 | P6: https://www.sec.gov/Archives/edgar/data/21344/000162828026010047/ko-20251231.htm | Q6: 5
A7: PepsiCo, Inc. | B7: PEP | C7: 2021 | D7: 2021-12-25 | E7: 79474 | F7: 70372 | G7: 42399 | H7: 11162 | I7: 7618 | J7: 7120 | K7: 92377 | L7: 5.49 | M7: 173.71001 | N7: 2021-12-31 | O7: 0000077476-22-000010 | P7: https://www.sec.gov/Archives/edgar/data/77476/000007747622000010/pep-20211225.htm | Q7: 5
A8: PepsiCo, Inc. | B8: PEP | C8: 2022 | D8: 2022-12-31 | E8: 86392 | F8: 79474 | G8: 45816 | H8: 11512 | I8: 8910 | J8: 7618 | K8: 92187 | L8: 6.42 | M8: 180.66 | N8: 2022-12-30 | O8: 0000077476-23-000007 | P8: https://www.sec.gov/Archives/edgar/data/77476/000007747623000007/pep-20221231.htm | Q8: 5
A9: PepsiCo, Inc. | B9: PEP | C9: 2023 | D9: 2023-12-30 | E9: 91471 | F9: 86392 | G9: 49590 | H9: 11986 | I9: 9074 | J9: 8910 | K9: 100495 | L9: 6.56 | M9: 169.84 | N9: 2023-12-29 | O9: 0000077476-24-000008 | P9: https://www.sec.gov/Archives/edgar/data/77476/000007747624000008/pep-20231230.htm | Q9: 5
A10: PepsiCo, Inc. | B10: PEP | C10: 2024 | D10: 2024-12-28 | E10: 91854 | F10: 91471 | G10: 50110 | H10: 12887 | I10: 9578 | J10: 9074 | K10: 99467 | L10: 6.95 | M10: 152.06 | N10: 2024-12-31 | O10: 0000077476-25-000007 | P10: https://www.sec.gov/Archives/edgar/data/77476/000007747625000007/pep-20241228.htm | Q10: 5
A11: PepsiCo, Inc. | B11: PEP | C11: 2025 | D11: 2025-12-27 | E11: 93925 | F11: 91854 | G11: 50859 | H11: 11498 | I11: 8240 | J11: 9578 | K11: 107399 | L11: 6 | M11: 143.52 | N11: 2025-12-31 | O11: 0000077476-26-000007 | P11: https://www.sec.gov/Archives/edgar/data/77476/000007747626000007/pep-20251227.htm | Q11: 5

Sheet Calculations
A1: Company | B1: Fiscal_Year | C1: Revenue_Growth | D1: Net_Income_Growth | E1: Gross_Margin | F1: Operating_Margin | G1: Net_Margin | H1: Revenue_Index_FY2021 | I1: Net_Income_Index_FY2021 | J1: PE_Ratio_GAAP
A2: =Inputs!A2 -> The Coca-Cola Company | B2: =Inputs!C2 -> 2021 | C2: =Inputs!E2/Inputs!F2-1 -> 0.1708669 | D2: =Inputs!I2/Inputs!J2-1 -> 0.26126242 | E2: =Inputs!G2/Inputs!E2 -> 0.60271634 | F2: =Inputs!H2/Inputs!E2 -> 0.26666667 | G2: =Inputs!I2/Inputs!E2 -> 0.25277454 | H2: =Inputs!E2/Inputs!E2*100 -> 100 | I2: =Inputs!I2/Inputs!I2*100 -> 100 | J2: =Inputs!M2/Inputs!L2 -> 26.315555
A3: =Inputs!A3 -> The Coca-Cola Company | B3: =Inputs!C3 -> 2022 | C3: =Inputs!E3/Inputs!F3-1 -> 0.11250808 | D3: =Inputs!I3/Inputs!J3-1 -> -0.0234367 | E3: =Inputs!G3/Inputs!E3 -> 0.58143429 | F3: =Inputs!H3/Inputs!E3 -> 0.25367408 | G3: =Inputs!I3/Inputs!E3 -> 0.22188634 | H3: =Inputs!E3/Inputs!E2*100 -> 111.25081 | I3: =Inputs!I3/Inputs!I2*100 -> 97.65633 | J3: =Inputs!M3/Inputs!L3 -> 29.045662
A4: =Inputs!A4 -> The Coca-Cola Company | B4: =Inputs!C4 -> 2023 | C4: =Inputs!E4/Inputs!F4-1 -> 0.06394754 | D4: =Inputs!I4/Inputs!J4-1 -> 0.1228254 | E4: =Inputs!G4/Inputs!E4 -> 0.59522665 | F4: =Inputs!H4/Inputs!E4 -> 0.24721336 | G4: =Inputs!I4/Inputs!E4 -> 0.23416532 | H4: =Inputs!E4/Inputs!E2*100 -> 118.36502 | I4: =Inputs!I4/Inputs!I2*100 -> 109.65101 | J4: =Inputs!M4/Inputs!L4 -> 23.8583
A5: =Inputs!A5 -> The Coca-Cola Company | B5: =Inputs!C5 -> 2024 | C5: =Inputs!E5/Inputs!F5-1 -> 0.028565808 | D5: =Inputs!I5/Inputs!J5-1 -> -0.0077468732 | E5: =Inputs!G5/Inputs!E5 -> 0.61063301 | F5: =Inputs!H5/Inputs!E5 -> 0.21232018 | G5: =Inputs!I5/Inputs!E5 -> 0.2258983 | H5: =Inputs!E5/Inputs!E2*100 -> 121.74622 | I5: =Inputs!I5/Inputs!I2*100 -> 108.80156 | J5: =Inputs!M5/Inputs!L5 -> 25.308942
A6: =Inputs!A6 -> The Coca-Cola Company | B6: =Inputs!C6 -> 2025 | C6: =Inputs!E6/Inputs!F6-1 -> 0.018699135 | D6: =Inputs!I6/Inputs!J6-1 -> 0.23290377 | E6: =Inputs!G6/Inputs!E6 -> 0.61625748 | F6: =Inputs!H6/Inputs!E6 -> 0.28706118 | G6: =Inputs!I6/Inputs!E6 -> 0.27339855 | H6: =Inputs!E6/Inputs!E2*100 -> 124.02277 | I6: =Inputs!I6/Inputs!I2*100 -> 134.14185 | J6: =Inputs!M6/Inputs!L6 -> 22.996712
A7: =Inputs!A7 -> PepsiCo, Inc. | B7: =Inputs!C7 -> 2021 | C7: =Inputs!E7/Inputs!F7-1 -> 0.12934122 | D7: =Inputs!I7/Inputs!J7-1 -> 0.06994382 | E7: =Inputs!G7/Inputs!E7 -> 0.53349523 | F7: =Inputs!H7/Inputs!E7 -> 0.14044845 | G7: =Inputs!I7/Inputs!E7 -> 0.095855248 | H7: =Inputs!E7/Inputs!E7*100 -> 100 | I7: =Inputs!I7/Inputs!I7*100 -> 100 | J7: =Inputs!M7/Inputs!L7 -> 31.641167
A8: =Inputs!A8 -> PepsiCo, Inc. | B8: =Inputs!C8 -> 2022 | C8: =Inputs!E8/Inputs!F8-1 -> 0.087047336 | D8: =Inputs!I8/Inputs!J8-1 -> 0.16959832 | E8: =Inputs!G8/Inputs!E8 -> 0.53032688 | F8: =Inputs!H8/Inputs!E8 -> 0.13325308 | G8: =Inputs!I8/Inputs!E8 -> 0.10313455 | H8: =Inputs!E8/Inputs!E7*100 -> 108.70473 | I8: =Inputs!I8/Inputs!I7*100 -> 116.95983 | J8: =Inputs!M8/Inputs!L8 -> 28.140187
A9: =Inputs!A9 -> PepsiCo, Inc. | B9: =Inputs!C9 -> 2023 | C9: =Inputs!E9/Inputs!F9-1 -> 0.058790166 | D9: =Inputs!I9/Inputs!J9-1 -> 0.018406285 | E9: =Inputs!G9/Inputs!E9 -> 0.54213904 | F9: =Inputs!H9/Inputs!E9 -> 0.13103607 | G9: =Inputs!I9/Inputs!E9 -> 0.09920084 | H9: =Inputs!E9/Inputs!E7*100 -> 115.0955 | I9: =Inputs!I9/Inputs!I7*100 -> 119.11263 | J9: =Inputs!M9/Inputs!L9 -> 25.890243
A10: =Inputs!A10 -> PepsiCo, Inc. | B10: =Inputs!C10 -> 2024 | C10: =Inputs!E10/Inputs!F10-1 -> 0.0041871194 | D10: =Inputs!I10/Inputs!J10-1 -> 0.055543311 | E10: =Inputs!G10/Inputs!E10 -> 0.54553966 | F10: =Inputs!H10/Inputs!E10 -> 0.14029873 | G10: =Inputs!I10/Inputs!E10 -> 0.10427417 | H10: =Inputs!E10/Inputs!E7*100 -> 115.57742 | I10: =Inputs!I10/Inputs!I7*100 -> 125.72854 | J10: =Inputs!M10/Inputs!L10 -> 21.879136
A11: =Inputs!A11 -> PepsiCo, Inc. | B11: =Inputs!C11 -> 2025 | C11: =Inputs!E11/Inputs!F11-1 -> 0.02254665 | D11: =Inputs!I11/Inputs!J11-1 -> -0.13969513 | E11: =Inputs!G11/Inputs!E11 -> 0.54148523 | F11: =Inputs!H11/Inputs!E11 -> 0.12241682 | G11: =Inputs!I11/Inputs!E11 -> 0.087729571 | H11: =Inputs!E11/Inputs!E7*100 -> 118.18331 | I11: =Inputs!I11/Inputs!I7*100 -> 108.16487 | J11: =Inputs!M11/Inputs!L11 -> 23.920001

Sheet Summary
A1: Metric | B1: Coca-Cola (KO) | C1: PepsiCo (PEP) | D1: Difference (KO minus PEP) | E1: Note
A2: Revenue FY2021 (USD M) | B2: =Inputs!E2 -> 38655 | C2: =Inputs!E7 -> 79474 | D2: =B2-C2 -> -40819
A3: Revenue FY2025 (USD M) | B3: =Inputs!E6 -> 47941 | C3: =Inputs!E11 -> 93925 | D3: =B3-C3 -> -45984
A4: Revenue CAGR FY2021 to FY2025 (4 intervals) | B4: =(Inputs!E6/Inputs!E2)^(1/4)-1 -> 0.055298578 | C4: =(Inputs!E11/Inputs!E7)^(1/4)-1 -> 0.042651165 | D4: =(B4-C4)*100 -> 1.2647412 | E4: Difference in percentage points
A5: Operating income CAGR FY2021 to FY2025 | B5: =(Inputs!H6/Inputs!H2)^(1/4)-1 -> 0.07492159 | C5: =(Inputs!H11/Inputs!H7)^(1/4)-1 -> 0.0074420441 | D5: =(B5-C5)*100 -> 6.7479546
A6: Net income CAGR FY2021 to FY2025 | B6: =(Inputs!I6/Inputs!I2)^(1/4)-1 -> 0.076195252 | C6: =(Inputs!I11/Inputs!I7)^(1/4)-1 -> 0.019815388 | D6: =(B6-C6)*100 -> 5.6379863 | E6: Endpoint-sensitive: FY2025 GAAP results include items not analysed here
A7: Average gross margin (5 yrs) | B7: =AVERAGE(Calculations!E2:E6) -> 0.60125355 | C7: =AVERAGE(Calculations!E7:E11) -> 0.53859721 | D7: =(B7-C7)*100 -> 6.2656344
A8: Average operating margin (5 yrs) | B8: =AVERAGE(Calculations!F2:F6) -> 0.25338709 | C8: =AVERAGE(Calculations!F7:F11) -> 0.13349063 | D8: =(B8-C8)*100 -> 11.989646 | E8: Simple average of five annual margins
A9: Average net margin (5 yrs) | B9: =AVERAGE(Calculations!G2:G6) -> 0.24162461 | C9: =AVERAGE(Calculations!G7:G11) -> 0.098038877 | D9: =(B9-C9)*100 -> 14.358573
A10: FY2025 operating margin | B10: =Calculations!F6 -> 0.28706118 | C10: =Calculations!F11 -> 0.12241682 | D10: =(B10-C10)*100 -> 16.464436
A11: FY2025 net margin | B11: =Calculations!G6 -> 0.27339855 | C11: =Calculations!G11 -> 0.087729571 | D11: =(B11-C11)*100 -> 18.566898
A12: Years (of 5) with BOTH revenue and net income up | B12: =COUNTIFS(Calculations!C2:C6,">0",Calculations!D2:D6,">0") -> 3 | C12: =COUNTIFS(Calculations!C7:C11,">0",Calculations!D7:D11,">0") -> 4 | D12: =B12-C12 -> -1
A13: GAAP P/E on 2025-12-31 (x) | B13: =Calculations!J6 -> 22.996712 | C13: =Calculations!J11 -> 23.920001 | D13: =B13-C13 -> -0.92328898 | E13: Close on 2025-12-31 / FY2025 diluted GAAP EPS
A15: P/E premium of PEP over KO on 2025-12-31 (%) | B15: =C13/B13-1 -> 0.040148739
A16: P/E difference PEP minus KO by year-end (x):
A17: 2021 (close on year-end) | B17: =Calculations!J7-Calculations!J2 -> 5.3256118
A18: 2022 (close on year-end) | B18: =Calculations!J8-Calculations!J3 -> -0.90547489
A19: 2023 (close on year-end) | B19: =Calculations!J9-Calculations!J4 -> 2.0319436
A20: 2024 (close on year-end) | B20: =Calculations!J10-Calculations!J5 -> -3.4298061
A21: 2025 (close on year-end) | B21: =Calculations!J11-Calculations!J6 -> 0.92328898

Sheet Verification
A1: Company | B1: Metric | C1: Fiscal_Year | D1: Value_in_workbook | E1: 10-K document matched | F1: Result
A2: KO | B2: Revenue | C2: 2021 | D2: 38655 | E2: https://www.sec.gov/Archives/edgar/data/21344/000002134424000009/ko-20231231.htm | F2: Matched to 10-K income statement text
A3: KO | B3: GrossProfit | C3: 2021 | D3: 23298 | E3: https://www.sec.gov/Archives/edgar/data/21344/000002134424000009/ko-20231231.htm | F3: Matched to 10-K income statement text
A4: KO | B4: OperatingIncome | C4: 2021 | D4: 10308 | E4: https://www.sec.gov/Archives/edgar/data/21344/000002134424000009/ko-20231231.htm | F4: Matched to 10-K income statement text
A5: KO | B5: NetIncome | C5: 2021 | D5: 9771 | E5: https://www.sec.gov/Archives/edgar/data/21344/000002134424000009/ko-20231231.htm | F5: Matched to 10-K income statement text
A6: KO | B6: EPS_Diluted | C6: 2021 | D6: 2.25 | E6: https://www.sec.gov/Archives/edgar/data/21344/000002134424000009/ko-20231231.htm | F6: Matched to 10-K income statement text
A7: KO | B7: Revenue | C7: 2022 | D7: 43004 | E7: https://www.sec.gov/Archives/edgar/data/21344/000002134424000009/ko-20231231.htm | F7: Matched to 10-K income statement text
A8: KO | B8: GrossProfit | C8: 2022 | D8: 25004 | E8: https://www.sec.gov/Archives/edgar/data/21344/000002134424000009/ko-20231231.htm | F8: Matched to 10-K income statement text
A9: KO | B9: OperatingIncome | C9: 2022 | D9: 10909 | E9: https://www.sec.gov/Archives/edgar/data/21344/000002134424000009/ko-20231231.htm | F9: Matched to 10-K income statement text
A10: KO | B10: NetIncome | C10: 2022 | D10: 9542 | E10: https://www.sec.gov/Archives/edgar/data/21344/000002134424000009/ko-20231231.htm | F10: Matched to 10-K income statement text
A11: KO | B11: EPS_Diluted | C11: 2022 | D11: 2.19 | E11: https://www.sec.gov/Archives/edgar/data/21344/000002134424000009/ko-20231231.htm | F11: Matched to 10-K income statement text
A12: KO | B12: Revenue | C12: 2023 | D12: 45754 | E12: https://www.sec.gov/Archives/edgar/data/21344/000002134424000009/ko-20231231.htm | F12: Matched to 10-K income statement text
A13: KO | B13: GrossProfit | C13: 2023 | D13: 27234 | E13: https://www.sec.gov/Archives/edgar/data/21344/000002134424000009/ko-20231231.htm | F13: Matched to 10-K income statement text
... A51: PEP | B51: EPS_Diluted | C51: 2025 | D51: 6 | E51: https://www.sec.gov/Archives/edgar/data/77476/000007747626000007/pep-20251227.htm | F51: Matched to 10-K income statement text

Sheet Checks
A1: Company | B1: Fiscal_Year | C1: Metric | D1: Workbook value | E1: CSV value (Tableau) | F1: Abs difference
A2: KO | B2: 2021 | C2: Revenue_Growth_Pct | D2: =Calculations!C2*100 -> 17.08669 | E2: 17.0867 | F2: =ABS(D2-E2) -> 9.5050585e-06
A3: KO | B3: 2021 | C3: Operating_Margin_Pct | D3: =Calculations!F2*100 -> 26.666667 | E3: 26.6667 | F3: =ABS(D3-E3) -> 3.3333333e-05
A4: KO | B4: 2021 | C4: Net_Margin_Pct | D4: =Calculations!G2*100 -> 25.277454 | E4: 25.2775 | F4: =ABS(D4-E4) -> 4.5595654e-05
A5: KO | B5: 2021 | C5: PE_Ratio_GAAP | D5: =Calculations!J2*1 -> 26.315555 | E5: 26.3156 | F5: =ABS(D5-E5) -> 4.4851345e-05
A6: KO | B6: 2022 | C6: Revenue_Growth_Pct | D6: =Calculations!C3*100 -> 11.250808 | E6: 11.2508 | F6: =ABS(D6-E6) -> 8.4335791e-06
A7: KO | B7: 2022 | C7: Operating_Margin_Pct | D7: =Calculations!F3*100 -> 25.367408 | E7: 25.3674 | F7: =ABS(D7-E7) -> 7.6830062e-06
A8: KO | B8: 2022 | C8: Net_Margin_Pct | D8: =Calculations!G3*100 -> 22.188634 | E8: 22.1886 | F8: =ABS(D8-E8) -> 3.3615478e-05
A9: KO | B9: 2022 | C9: PE_Ratio_GAAP | D9: =Calculations!J3*1 -> 29.045662 | E9: 29.0457 | F9: =ABS(D9-E9) -> 3.7620844e-05
A10: KO | B10: 2023 | C10: Revenue_Growth_Pct | D10: =Calculations!C4*100 -> 6.394754 | E10: 6.3948 | F10: =ABS(D10-E10) -> 4.6023626e-05
A11: KO | B11: 2023 | C11: Operating_Margin_Pct | D11: =Calculations!F4*100 -> 24.721336 | E11: 24.7213 | F11: =ABS(D11-E11) -> 3.5839489e-05
A12: KO | B12: 2023 | C12: Net_Margin_Pct | D12: =Calculations!G4*100 -> 23.416532 | E12: 23.4165 | F12: =ABS(D12-E12) -> 3.1887922e-05
A13: KO | B13: 2023 | C13: PE_Ratio_GAAP | D13: =Calculations!J4*1 -> 23.8583 | E13: 23.8583 | F13: =ABS(D13-E13) -> 2.8130535e-07
A14: KO | B14: 2024 | C14: Revenue_Growth_Pct | D14: =Calculations!C5*100 -> 2.8565808 | E14: 2.8566 | F14: =ABS(D14-E14) -> 1.9154609e-05
A15: KO | B15: 2024 | C15: Operating_Margin_Pct | D15: =Calculations!F5*100 -> 21.232018 | E15: 21.232 | F15: =ABS(D15-E15) -> 1.8019167e-05
A16: KO | B16: 2024 | C16: Net_Margin_Pct | D16: =Calculations!G5*100 -> 22.58983 | E16: 22.5898 | F16: =ABS(D16-E16) -> 3.0220352e-05
A17: KO | B17: 2024 | C17: PE_Ratio_GAAP | D17: =Calculations!J5*1 -> 25.308942 | E17: 25.3089 | F17: =ABS(D17-E17) -> 4.2407127e-05
A18: KO | B18: 2025 | C18: Revenue_Growth_Pct | D18: =Calculations!C6*100 -> 1.8699135 | E18: 1.8699 | F18: =ABS(D18-E18) -> 1.35165e-05
A19: KO | B19: 2025 | C19: Operating_Margin_Pct | D19: =Calculations!F6*100 -> 28.706118 | E19: 28.7061 | F19: =ABS(D19-E19) -> 1.793663e-05
A20: KO | B20: 2025 | C20: Net_Margin_Pct | D20: =Calculations!G6*100 -> 27.339855 | E20: 27.3399 | F20: =ABS(D20-E20) -> 4.4761269e-05
A21: KO | B21: 2025 | C21: PE_Ratio_GAAP | D21: =Calculations!J6*1 -> 22.996712 | E21: 22.9967 | F21: =ABS(D21-E21) -> 1.1730957e-05
A22: PEP | B22: 2021 | C22: Revenue_Growth_Pct | D22: =Calculations!C7*100 -> 12.934122 | E22: 12.9341 | F22: =ABS(D22-E22) -> 2.1525607e-05
A23: PEP | B23: 2021 | C23: Operating_Margin_Pct | D23: =Calculations!F7*100 -> 14.044845 | E23: 14.0448 | F23: =ABS(D23-E23) -> 4.4854921e-05
A24: PEP | B24: 2021 | C24: Net_Margin_Pct | D24: =Calculations!G7*100 -> 9.5855248 | E24: 9.5855 | F24: =ABS(D24-E24) -> 2.4825729e-05
A25: PEP | B25: 2021 | C25: PE_Ratio_GAAP | D25: =Calculations!J7*1 -> 31.641167 | E25: 31.6412 | F25: =ABS(D25-E25) -> 3.3021154e-05
A26: PEP | B26: 2022 | C26: Revenue_Growth_Pct | D26: =Calculations!C8*100 -> 8.7047336 | E26: 8.7047 | F26: =ABS(D26-E26) -> 3.3623575e-05
A27: PEP | B27: 2022 | C27: Operating_Margin_Pct | D27: =Calculations!F8*100 -> 13.325308 | E27: 13.3253 | F27: =ABS(D27-E27) -> 7.8988795e-06
A28: PEP | B28: 2022 | C28: Net_Margin_Pct | D28: =Calculations!G8*100 -> 10.313455 | E28: 10.3135 | F28: =ABS(D28-E28) -> 4.5050468e-05
A29: PEP | B29: 2022 | C29: PE_Ratio_GAAP | D29: =Calculations!J8*1 -> 28.140187 | E29: 28.1402 | F29: =ABS(D29-E29) -> 1.251369e-05
A30: PEP | B30: 2023 | C30: Revenue_Growth_Pct | D30: =Calculations!C9*100 -> 5.8790166 | E30: 5.879 | F30: =ABS(D30-E30) -> 1.6575609e-05
A31: PEP | B31: 2023 | C31: Operating_Margin_Pct | D31: =Calculations!F9*100 -> 13.103607 | E31: 13.1036 | F31: =ABS(D31-E31) -> 6.6075587e-06
A32: PEP | B32: 2023 | C32: Net_Margin_Pct | D32: =Calculations!G9*100 -> 9.920084 | E32: 9.9201 | F32: =ABS(D32-E32) -> 1.6038963e-05
A33: PEP | B33: 2023 | C33: PE_Ratio_GAAP | D33: =Calculations!J9*1 -> 25.890243 | E33: 25.8902 | F33: =ABS(D33-E33) -> 4.3344191e-05
A34: PEP | B34: 2024 | C34: Revenue_Growth_Pct | D34: =Calculations!C10*100 -> 0.41871194 | E34: 0.4187 | F34: =ABS(D34-E34) -> 1.194149e-05
A35: PEP | B35: 2024 | C35: Operating_Margin_Pct | D35: =Calculations!F10*100 -> 14.029873 | E35: 14.0299 | F35: =ABS(D35-E35) -> 2.6505106e-05
A36: PEP | B36: 2024 | C36: Net_Margin_Pct | D36: =Calculations!G10*100 -> 10.427417 | E36: 10.4274 | F36: =ABS(D36-E36) -> 1.7423302e-05
A37: PEP | B37: 2024 | C37: PE_Ratio_GAAP | D37: =Calculations!J10*1 -> 21.879136 | E37: 21.8791 | F37: =ABS(D37-E37) -> 3.6339366e-05
A38: PEP | B38: 2025 | C38: Revenue_Growth_Pct | D38: =Calculations!C11*100 -> 2.254665 | E38: 2.2547 | F38: =ABS(D38-E38) -> 3.4988133e-05
A39: PEP | B39: 2025 | C39: Operating_Margin_Pct | D39: =Calculations!F11*100 -> 12.241682 | E39: 12.2417 | F39: =ABS(D39-E39) -> 1.7806761e-05
A40: PEP | B40: 2025 | C40: Net_Margin_Pct | D40: =Calculations!G11*100 -> 8.7729571 | E40: 8.773 | F40: =ABS(D40-E40) -> 4.285334e-05
...

Sheet Limitations
A1: COMPARABILITY LIMITATIONS AND EXCLUSIONS
A2: 1. Different business mixes: KO sells mainly beverage concentrates/syrups and finished beverages through bottling partners; PEP combines beverages with a large snack and food business. Margin gaps reflect business model differences that this study does not isolate.
A3: 2. Different fiscal calendars: KO ends Dec 31; PEP ends on the last Saturday of December (Dec 25, 2021; Dec 31, 2022; Dec 30, 2023; Dec 28, 2024; Dec 27, 2025). Period lengths were not adjusted.
A4: 3. GAAP results: KO operating income includes 'Other operating charges' (10-K: $1,261M FY2025, $4,163M FY2024, $1,951M FY2023). Non-GAAP/comparable measures were NOT used because they are not audited line items and cannot be sourced consistently.
A5: 4. Net margin can exceed operating margin (KO FY2024-25) because net income includes non-operating items; not decomposed here.
A6: 5. Total debt and EV/EBITDA were EXCLUDED: XBRL debt tags differ across years and between companies (finance leases, commercial paper, current maturities), so a consistent definition could not be verified.
A7: 6. Prices are calendar year-end closes from Yahoo Finance (secondary source). P/E uses FY GAAP diluted EPS; PEP fiscal year-end is a few days before the price date in some years.
A8: 7. FY2021 growth uses FY2020 revenue and net income from the FY2020 10-K XBRL data (not text-matched).
A9: 8. Total assets are from XBRL data and were not text-matched.
A10: 9. Observation vs interpretation: nothing here establishes why investors pay a given multiple. This is a descriptive comparison, not a valuation model or recommendation.
